2023-03-22 11:15:09,350 INFO    StreamThr :9488 [internal.py:wandb_internal():87] W&B internal server running at pid: 9488, started at: 2023-03-22 11:15:09.349468
2023-03-22 11:15:09,351 DEBUG   HandlerThread:9488 [handler.py:handle_request():144] handle_request: status
2023-03-22 11:15:09,351 INFO    WriterThread:9488 [datastore.py:open_for_write():85] open: D:\d2l-zh\pytorch\object_detection\yolov5-7.0-SeaDronesSee\wandb\run-20230322_111509-dfdw2013\run-dfdw2013.wandb
2023-03-22 11:15:09,354 DEBUG   SenderThread:9488 [sender.py:send():336] send: header
2023-03-22 11:15:09,354 DEBUG   SenderThread:9488 [sender.py:send():336] send: run
2023-03-22 11:15:09,361 INFO    SenderThread:9488 [sender.py:_maybe_setup_resume():722] checking resume status for None/train/dfdw2013
2023-03-22 11:15:12,550 INFO    SenderThread:9488 [retry.py:__call__():172] Retry attempt failed:
Traceback (most recent call last):
  File "D:\Anaconda3\envs\d2l\lib\site-packages\urllib3\connectionpool.py", line 692, in urlopen
    conn = self._get_conn(timeout=pool_timeout)
  File "D:\Anaconda3\envs\d2l\lib\site-packages\urllib3\connectionpool.py", line 281, in _get_conn
    return conn or self._new_conn()
  File "D:\Anaconda3\envs\d2l\lib\site-packages\urllib3\connectionpool.py", line 1011, in _new_conn
    raise SSLError(
urllib3.exceptions.SSLError: Can't connect to HTTPS URL because the SSL module is not available.

During handling of the above exception, another exception occurred:

Traceback (most recent call last):
  File "D:\Anaconda3\envs\d2l\lib\site-packages\requests\adapters.py", line 489, in send
    resp = conn.urlopen(
  File "D:\Anaconda3\envs\d2l\lib\site-packages\urllib3\connectionpool.py", line 787, in urlopen
    retries = retries.increment(
  File "D:\Anaconda3\envs\d2l\lib\site-packages\urllib3\util\retry.py", line 592, in increment
    raise MaxRetryError(_pool, url, error or ResponseError(cause))
urllib3.exceptions.MaxRetryError: HTTPSConnectionPool(host='api.wandb.ai', port=443): Max retries exceeded with url: /graphql (Caused by SSLError("Can't connect to HTTPS URL because the SSL module is not available."))

During handling of the above exception, another exception occurred:

Traceback (most recent call last):
  File "D:\Anaconda3\envs\d2l\lib\site-packages\wandb\sdk\lib\retry.py", line 131, in __call__
    result = self._call_fn(*args, **kwargs)
  File "D:\Anaconda3\envs\d2l\lib\site-packages\wandb\sdk\internal\internal_api.py", line 243, in execute
    return self.client.execute(*args, **kwargs)  # type: ignore
  File "D:\Anaconda3\envs\d2l\lib\site-packages\wandb\vendor\gql-0.2.0\wandb_gql\client.py", line 52, in execute
    result = self._get_result(document, *args, **kwargs)
  File "D:\Anaconda3\envs\d2l\lib\site-packages\wandb\vendor\gql-0.2.0\wandb_gql\client.py", line 60, in _get_result
    return self.transport.execute(document, *args, **kwargs)
  File "D:\Anaconda3\envs\d2l\lib\site-packages\wandb\vendor\gql-0.2.0\wandb_gql\transport\requests.py", line 38, in execute
    request = requests.post(self.url, **post_args)
  File "D:\Anaconda3\envs\d2l\lib\site-packages\requests\api.py", line 115, in post
    return request("post", url, data=data, json=json, **kwargs)
  File "D:\Anaconda3\envs\d2l\lib\site-packages\requests\api.py", line 59, in request
    return session.request(method=method, url=url, **kwargs)
  File "D:\Anaconda3\envs\d2l\lib\site-packages\requests\sessions.py", line 587, in request
    resp = self.send(prep, **send_kwargs)
  File "D:\Anaconda3\envs\d2l\lib\site-packages\requests\sessions.py", line 701, in send
    r = adapter.send(request, **kwargs)
  File "D:\Anaconda3\envs\d2l\lib\site-packages\requests\adapters.py", line 563, in send
    raise SSLError(e, request=request)
requests.exceptions.SSLError: HTTPSConnectionPool(host='api.wandb.ai', port=443): Max retries exceeded with url: /graphql (Caused by SSLError("Can't connect to HTTPS URL because the SSL module is not available."))
2023-03-22 11:15:14,403 DEBUG   HandlerThread:9488 [handler.py:handle_request():144] handle_request: keepalive
2023-03-22 11:15:19,457 DEBUG   HandlerThread:9488 [handler.py:handle_request():144] handle_request: keepalive
2023-03-22 11:15:24,490 DEBUG   HandlerThread:9488 [handler.py:handle_request():144] handle_request: keepalive
2023-03-22 11:15:29,514 DEBUG   HandlerThread:9488 [handler.py:handle_request():144] handle_request: keepalive
2023-03-22 11:15:34,543 DEBUG   HandlerThread:9488 [handler.py:handle_request():144] handle_request: keepalive
2023-03-22 11:15:39,566 DEBUG   HandlerThread:9488 [handler.py:handle_request():144] handle_request: keepalive
2023-03-22 11:15:44,595 DEBUG   HandlerThread:9488 [handler.py:handle_request():144] handle_request: keepalive
2023-03-22 11:15:49,615 DEBUG   HandlerThread:9488 [handler.py:handle_request():144] handle_request: keepalive
2023-03-22 11:15:54,661 DEBUG   HandlerThread:9488 [handler.py:handle_request():144] handle_request: keepalive
2023-03-22 11:15:59,688 DEBUG   HandlerThread:9488 [handler.py:handle_request():144] handle_request: keepalive
2023-03-22 11:16:04,720 DEBUG   HandlerThread:9488 [handler.py:handle_request():144] handle_request: keepalive
2023-03-22 11:16:09,771 DEBUG   HandlerThread:9488 [handler.py:handle_request():144] handle_request: cancel
2023-03-22 11:16:09,771 DEBUG   HandlerThread:9488 [handler.py:handle_request():144] handle_request: cancel
2023-03-22 11:16:09,772 DEBUG   SenderThread:9488 [sender.py:send():345] Record cancelled: run
2023-03-22 11:16:09,772 DEBUG   HandlerThread:9488 [handler.py:handle_request():144] handle_request: status_report
2023-03-22 11:16:13,801 INFO    MainThread:9488 [internal.py:handle_exit():77] Internal process exited
