2023-03-22 10:56:57,139 INFO    StreamThr :1732 [internal.py:wandb_internal():87] W&B internal server running at pid: 1732, started at: 2023-03-22 10:56:57.138004
2023-03-22 10:56:57,140 DEBUG   HandlerThread:1732 [handler.py:handle_request():144] handle_request: status
2023-03-22 10:56:57,141 INFO    WriterThread:1732 [datastore.py:open_for_write():85] open: D:\d2l-zh\pytorch\object_detection\yolov5-7.0-SeaDronesSee\wandb\run-20230322_105657-0kl68k09\run-0kl68k09.wandb
2023-03-22 10:56:57,143 DEBUG   SenderThread:1732 [sender.py:send():336] send: header
2023-03-22 10:56:57,143 DEBUG   SenderThread:1732 [sender.py:send():336] send: run
2023-03-22 10:56:57,151 INFO    SenderThread:1732 [sender.py:_maybe_setup_resume():722] checking resume status for None/train/0kl68k09
2023-03-22 10:57:00,650 INFO    SenderThread:1732 [retry.py:__call__():172] Retry attempt failed:
Traceback (most recent call last):
  File "D:\Anaconda3\envs\d2l\lib\site-packages\urllib3\connectionpool.py", line 692, in urlopen
    conn = self._get_conn(timeout=pool_timeout)
  File "D:\Anaconda3\envs\d2l\lib\site-packages\urllib3\connectionpool.py", line 281, in _get_conn
    return conn or self._new_conn()
  File "D:\Anaconda3\envs\d2l\lib\site-packages\urllib3\connectionpool.py", line 1011, in _new_conn
    raise SSLError(
urllib3.exceptions.SSLError: Can't connect to HTTPS URL because the SSL module is not available.

During handling of the above exception, another exception occurred:

Traceback (most recent call last):
  File "D:\Anaconda3\envs\d2l\lib\site-packages\requests\adapters.py", line 489, in send
    resp = conn.urlopen(
  File "D:\Anaconda3\envs\d2l\lib\site-packages\urllib3\connectionpool.py", line 787, in urlopen
    retries = retries.increment(
  File "D:\Anaconda3\envs\d2l\lib\site-packages\urllib3\util\retry.py", line 592, in increment
    raise MaxRetryError(_pool, url, error or ResponseError(cause))
urllib3.exceptions.MaxRetryError: HTTPSConnectionPool(host='api.wandb.ai', port=443): Max retries exceeded with url: /graphql (Caused by SSLError("Can't connect to HTTPS URL because the SSL module is not available."))

During handling of the above exception, another exception occurred:

Traceback (most recent call last):
  File "D:\Anaconda3\envs\d2l\lib\site-packages\wandb\sdk\lib\retry.py", line 131, in __call__
    result = self._call_fn(*args, **kwargs)
  File "D:\Anaconda3\envs\d2l\lib\site-packages\wandb\sdk\internal\internal_api.py", line 243, in execute
    return self.client.execute(*args, **kwargs)  # type: ignore
  File "D:\Anaconda3\envs\d2l\lib\site-packages\wandb\vendor\gql-0.2.0\wandb_gql\client.py", line 52, in execute
    result = self._get_result(document, *args, **kwargs)
  File "D:\Anaconda3\envs\d2l\lib\site-packages\wandb\vendor\gql-0.2.0\wandb_gql\client.py", line 60, in _get_result
    return self.transport.execute(document, *args, **kwargs)
  File "D:\Anaconda3\envs\d2l\lib\site-packages\wandb\vendor\gql-0.2.0\wandb_gql\transport\requests.py", line 38, in execute
    request = requests.post(self.url, **post_args)
  File "D:\Anaconda3\envs\d2l\lib\site-packages\requests\api.py", line 115, in post
    return request("post", url, data=data, json=json, **kwargs)
  File "D:\Anaconda3\envs\d2l\lib\site-packages\requests\api.py", line 59, in request
    return session.request(method=method, url=url, **kwargs)
  File "D:\Anaconda3\envs\d2l\lib\site-packages\requests\sessions.py", line 587, in request
    resp = self.send(prep, **send_kwargs)
  File "D:\Anaconda3\envs\d2l\lib\site-packages\requests\sessions.py", line 701, in send
    r = adapter.send(request, **kwargs)
  File "D:\Anaconda3\envs\d2l\lib\site-packages\requests\adapters.py", line 563, in send
    raise SSLError(e, request=request)
requests.exceptions.SSLError: HTTPSConnectionPool(host='api.wandb.ai', port=443): Max retries exceeded with url: /graphql (Caused by SSLError("Can't connect to HTTPS URL because the SSL module is not available."))
2023-03-22 10:57:02,184 DEBUG   HandlerThread:1732 [handler.py:handle_request():144] handle_request: keepalive
2023-03-22 10:57:07,198 DEBUG   HandlerThread:1732 [handler.py:handle_request():144] handle_request: keepalive
2023-03-22 10:57:12,248 DEBUG   HandlerThread:1732 [handler.py:handle_request():144] handle_request: keepalive
2023-03-22 10:57:17,287 DEBUG   HandlerThread:1732 [handler.py:handle_request():144] handle_request: keepalive
2023-03-22 10:57:22,317 DEBUG   HandlerThread:1732 [handler.py:handle_request():144] handle_request: keepalive
2023-03-22 10:57:27,369 DEBUG   HandlerThread:1732 [handler.py:handle_request():144] handle_request: keepalive
2023-03-22 10:57:32,406 DEBUG   HandlerThread:1732 [handler.py:handle_request():144] handle_request: keepalive
2023-03-22 10:57:37,431 DEBUG   HandlerThread:1732 [handler.py:handle_request():144] handle_request: keepalive
2023-03-22 10:57:42,464 DEBUG   HandlerThread:1732 [handler.py:handle_request():144] handle_request: keepalive
2023-03-22 10:57:47,497 DEBUG   HandlerThread:1732 [handler.py:handle_request():144] handle_request: keepalive
2023-03-22 10:57:52,542 DEBUG   HandlerThread:1732 [handler.py:handle_request():144] handle_request: keepalive
2023-03-22 10:57:57,591 DEBUG   HandlerThread:1732 [handler.py:handle_request():144] handle_request: cancel
2023-03-22 10:57:57,591 DEBUG   HandlerThread:1732 [handler.py:handle_request():144] handle_request: cancel
2023-03-22 10:57:57,592 DEBUG   SenderThread:1732 [sender.py:send():345] Record cancelled: run
2023-03-22 10:57:57,592 DEBUG   HandlerThread:1732 [handler.py:handle_request():144] handle_request: status_report
2023-03-22 10:58:01,625 INFO    MainThread:1732 [internal.py:handle_exit():77] Internal process exited
